<?xml version="1.0" ?>
<!-- =================================================================================== -->
<!-- |    This document was autogenerated by xacro from LIMBERO_UPDATE.xacro           | -->
<!-- |    EDITING THIS FILE BY HAND IS NOT RECOMMENDED                                 | -->
<!-- =================================================================================== -->
<robot name="LIMBERO">
  <gazebo>
    <!-- ros_control plugin -->
    <plugin filename="libgazebo_ros2_control.so" name="gazebo_ros2_control">
      <parameters>/home/ale/lbr_ws/install/lbr_description/share/lbr_description/config/lbr_controller_with_grieel.yaml</parameters>
    </plugin>
  </gazebo>
  <link name="base_link">
    <inertial>
      <origin rpy="0 0 0" xyz="0 0 -0.0030083"/>
      <mass value="3.1152"/>
      <inertia ixx="0.0036482" ixy="7.8081E-07" ixz="1.7521E-06" iyy="0.0062179" iyz="-1.4424E-06" izz="0.0034682"/>
    </inertial>
    <visual>
      <origin rpy="0 0 0" xyz="0 0 0"/>
      <geometry>
        <mesh filename="file:///home/ale/lbr_ws/install/lbr_description/share/lbr_description/meshes/base.STL" scale="1.0 1.0 1.0"/>
      </geometry>
      <material name="">
        <color rgba="0.2 0.2 0.2 1"/>
      </material>
    </visual>
    <collision>
      <origin rpy="0 0 0" xyz="0 0 0"/>
      <geometry>
        <mesh filename="file:///home/ale/lbr_ws/install/lbr_description/share/lbr_description/meshes/base.STL" scale="1.0 1.0 1.0"/>
      </geometry>
    </collision>
  </link>
  <gazebo reference="base_link">
    <material>Gazebo/Black</material>
    <visual>
      <material>
        <ambient>0.2 0.2 0.2 1</ambient>
        <diffuse>0.2 0.2 0.2 1</diffuse>
        <specular>0.01 0.01 0.01 1</specular>
        <emissive>0.01 0.01 0.01 1</emissive>
      </material>
    </visual>
  </gazebo>
  <joint name="LF_joint" type="fixed">
    <origin rpy="0 0 0.7853981633974483" xyz="0.14142135623730953 0.1414213562373095 0"/>
    <parent link="base_link"/>
    <child link="LF_limb_root"/>
  </joint>
  <link name="LF_limb_root">
    <inertial>
      <origin rpy="0 0 0" xyz="-0.015029 -7.7571E-11 -0.047318"/>
      <mass value="0.08459"/>
      <inertia ixx="2.1548E-05" ixy="-4.775E-14" ixz="-1.6188E-07" iyy="3.834E-05" iyz="-8.2973E-14" izz="3.1728E-05"/>
    </inertial>
    <visual>
      <origin rpy="0 0 0" xyz="0 0 0"/>
      <geometry>
        <mesh filename="file:///home/ale/lbr_ws/install/lbr_description/share/lbr_description/meshes/limb_root.STL"/>
      </geometry>
      <material name="">
        <color rgba="0.2 0.2 0.2 1"/>
      </material>
    </visual>
    <collision>
      <origin rpy="0 0 0" xyz="0 0 0"/>
      <geometry>
        <mesh filename="file:///home/ale/lbr_ws/install/lbr_description/share/lbr_description/meshes/limb_root.STL"/>
      </geometry>
    </collision>
  </link>
  <link name="LF_coxa">
    <inertial>
      <origin rpy="0 0 0" xyz="0.015938 0.00063302 -0.0015013"/>
      <mass value="0.09109"/>
      <inertia ixx="2.352E-05" ixy="-1.6188E-07" ixz="4.775E-14" iyy="3.3634E-05" iyz="8.2973E-14" izz="4.2122E-05"/>
    </inertial>
    <visual>
      <origin rpy="0 0 0" xyz="0 0 0"/>
      <geometry>
        <mesh filename="file:///home/ale/lbr_ws/install/lbr_description/share/lbr_description/meshes/coxa.STL"/>
      </geometry>
      <material name="">
        <color rgba="0.2 0.2 0.2 1"/>
      </material>
    </visual>
    <collision>
      <origin rpy="0 0 0" xyz="0 0 0"/>
      <geometry>
        <mesh filename="file:///home/ale/lbr_ws/install/lbr_description/share/lbr_description/meshes/coxa.STL"/>
      </geometry>
    </collision>
  </link>
  <joint name="LF_B2C" type="revolute">
    <origin rpy="0 0 0" xyz="0 0 0"/>
    <parent link="LF_limb_root"/>
    <child link="LF_coxa"/>
    <axis xyz="0 0 1"/>
    <limit effort="5" lower="-3.14" upper="3.14" velocity="5"/>
    <dynamics damping="0.1" friction="0.4"/>
  </joint>
  <link name="LF_femur">
    <inertial>
      <origin rpy="0 0 0" xyz="0.10083 0.00014739 -3.217E-08"/>
      <mass value="0.12821"/>
      <inertia ixx="3.7005E-05" ixy="-1.9987E-08" ixz="-3.8346E-12" iyy="2.9934E-05" iyz="2.5988E-11" izz="4.8164E-05"/>
    </inertial>
    <visual>
      <origin rpy="0 0 0" xyz="0 0 0"/>
      <geometry>
        <mesh filename="file:///home/ale/lbr_ws/install/lbr_description/share/lbr_description/meshes/femur.STL"/>
      </geometry>
      <material name="">
        <color rgba="0.2 0.2 0.2 1"/>
      </material>
    </visual>
    <collision>
      <origin rpy="0 0 0" xyz="0 0 0"/>
      <geometry>
        <mesh filename="file:///home/ale/lbr_ws/install/lbr_description/share/lbr_description/meshes/femur.STL"/>
      </geometry>
    </collision>
  </link>
  <joint name="LF_C2F" type="revolute">
    <origin rpy="0 0 0" xyz="0.031 0 0"/>
    <parent link="LF_coxa"/>
    <child link="LF_femur"/>
    <axis xyz="0 1 0"/>
    <limit effort="5" lower="-3.14" upper="3.14" velocity="5"/>
    <dynamics damping="0.1" friction="0.4"/>
  </joint>
  <link name="LF_tibia">
    <inertial>
      <origin rpy="0 0 0" xyz="0.10298 1.1638E-07 0.019231"/>
      <mass value="0.061841"/>
      <inertia ixx="1.5486E-05" ixy="4.7072E-09" ixz="2.5637E-06" iyy="2.1826E-05" iyz="2.414E-08" izz="2.8843E-05"/>
    </inertial>
    <visual>
      <origin rpy="0 0 0" xyz="0 0 0"/>
      <geometry>
        <mesh filename="file:///home/ale/lbr_ws/install/lbr_description/share/lbr_description/meshes/tibia.STL"/>
      </geometry>
      <material name="">
        <color rgba="0.2 0.2 0.2 1"/>
      </material>
    </visual>
    <collision>
      <origin rpy="0 0 0" xyz="0 0 0"/>
      <geometry>
        <mesh filename="file:///home/ale/lbr_ws/install/lbr_description/share/lbr_description/meshes/tibia.STL"/>
      </geometry>
    </collision>
  </link>
  <joint name="LF_F2T" type="revolute">
    <origin rpy="0 0 0" xyz="0.2 0 0"/>
    <parent link="LF_femur"/>
    <child link="LF_tibia"/>
    <axis xyz="0 1 0"/>
    <limit effort="5" lower="-3.14" upper="3.14" velocity="5"/>
    <dynamics damping="0.1" friction="0.4"/>
  </joint>
  <link name="LF_limb_end">
    <inertial>
      <origin rpy="0 0 0" xyz="-0.011645 0.00042918 -9.53E-12"/>
      <mass value="0.081999"/>
      <inertia ixx="1.3061E-05" ixy="-3.7211E-08" ixz="3.1094E-14" iyy="1.9634E-05" iyz="-3.9438E-17" izz="2.2308E-05"/>
    </inertial>
    <visual>
      <origin rpy="0 0 0" xyz="0 0 0"/>
      <geometry>
        <mesh filename="file:///home/ale/lbr_ws/install/lbr_description/share/lbr_description/meshes/limb_end.STL"/>
      </geometry>
      <material name="">
        <color rgba="0.2 0.2 0.2 1"/>
      </material>
    </visual>
    <collision>
      <origin rpy="0 0 0" xyz="0 0 0"/>
      <geometry>
        <mesh filename="file:///home/ale/lbr_ws/install/lbr_description/share/lbr_description/meshes/limb_end.STL"/>
      </geometry>
    </collision>
  </link>
  <joint name="LF_T2E" type="revolute">
    <origin rpy="0 0 0" xyz="0.2 0 0"/>
    <parent link="LF_tibia"/>
    <child link="LF_limb_end"/>
    <axis xyz="0 1 0"/>
    <limit effort="5" lower="-3.14" upper="3.14" velocity="5"/>
    <dynamics damping="0.1" friction="0.4"/>
  </joint>
  <!-- <xacro:limb_macro prefix="LH" parent="base_link" radius="135"/>
  <xacro:limb_macro prefix="RH" parent="base_link" radius="225"/>
  <xacro:limb_macro prefix="RF" parent="base_link" radius="315"/> -->
  <joint name="LF_E2grieel" type="fixed">
    <origin rpy="-1.5708 0 0" xyz="0 0 0"/>
    <parent link="LF_limb_end"/>
    <child link="LF_wristH_Link"/>
    <!-- <axis
        xyz="0 1 0" />
      <limit
        lower="0"
        upper="0"
        effort="0"
        velocity="0" /> -->
  </joint>
  <link name="LF_wristH_Link">
    <inertial>
      <origin rpy="0 0 0" xyz="0.011821 8.7424E-07 4.3619E-14"/>
      <mass value="0.00824"/>
      <inertia ixx="1.7943E-06" ixy="-3.8552E-19" ixz="7.4101E-19" iyy="2.9379E-06" iyz="-2.3646E-09" izz="1.6633E-06"/>
    </inertial>
    <visual>
      <origin rpy="0 0 0" xyz="0 0 0"/>
      <geometry>
        <mesh filename="file:///home/ale/lbr_ws/install/lbr_description/share/lbr_description/meshes/Grieel_gripper_mode/wristH_Link.STL"/>
      </geometry>
      <material name="">
        <color rgba="0.2 0.2 0.2 1"/>
      </material>
    </visual>
    <collision>
      <origin rpy="0 0 0" xyz="0 0 0"/>
      <geometry>
        <mesh filename="file:///home/ale/lbr_ws/install/lbr_description/share/lbr_description/meshes/Grieel_gripper_mode/wristH_Link.STL"/>
      </geometry>
    </collision>
  </link>
  <link name="LF_wristV_Link">
    <inertial>
      <origin rpy="0 0 0" xyz="0.0214166502499745 0.000471129500725836 0.0113219457469963"/>
      <mass value="0.102059813857681"/>
      <inertia ixx="2.51506057023328E-05" ixy="-5.87568310882068E-07" ixz="-5.02138918625881E-10" iyy="2.47069145197251E-05" iyz="-1.3142285327366E-09" izz="1.79824315026287E-05"/>
    </inertial>
    <visual>
      <origin rpy="0 0 0" xyz="0 0 0"/>
      <geometry>
        <mesh filename="file:///home/ale/lbr_ws/install/lbr_description/share/lbr_description/meshes/Grieel_gripper_mode/wristV_Link.STL"/>
      </geometry>
      <material name="">
        <color rgba="0.2 0.2 0.2 1"/>
      </material>
    </visual>
    <collision>
      <origin rpy="0 0 0" xyz="0 0 0"/>
      <geometry>
        <mesh filename="file:///home/ale/lbr_ws/install/lbr_description/share/lbr_description/meshes/Grieel_gripper_mode/wristV_Link.STL"/>
      </geometry>
    </collision>
  </link>
  <joint name="LF_wristH" type="revolute">
    <origin rpy="1.5708 0 0" xyz="0.025851 0 0"/>
    <parent link="LF_wristH_Link"/>
    <child link="LF_wristV_Link"/>
    <axis xyz="1 0 0"/>
    <limit effort="5" lower="-3.14159265358" upper="3.14159265358" velocity="5"/>
    <dynamics damping="0.1" friction="0.4"/>
  </joint>
  <link name="LF_driving_Link">
    <inertial>
      <origin rpy="0 0 0" xyz="5.44808065291863E-05 0.00431293338596027 0.0448909989385787"/>
      <mass value="0.132659951311712"/>
      <inertia ixx="3.76031003493078E-05" ixy="1.06164546307058E-08" ixz="7.08867360655478E-09" iyy="3.46919596241853E-05" iyz="4.14273177876885E-09" izz="4.32511275712205E-05"/>
    </inertial>
    <visual>
      <origin rpy="0 0 0" xyz="0 0 0"/>
      <geometry>
        <mesh filename="file:///home/ale/lbr_ws/install/lbr_description/share/lbr_description/meshes/Grieel_gripper_mode/driving_Link.STL"/>
      </geometry>
      <material name="">
        <color rgba="0.2 0.2 0.2 1"/>
      </material>
    </visual>
    <collision>
      <origin rpy="0 0 0" xyz="0 0 0"/>
      <geometry>
        <mesh filename="file:///home/ale/lbr_ws/install/lbr_description/share/lbr_description/meshes/Grieel_gripper_mode/driving_Link.STL"/>
      </geometry>
    </collision>
  </link>
  <joint name="LF_wristV" type="revolute">
    <origin rpy="0 0 0" xyz="0.0209 0 0.024008"/>
    <parent link="LF_wristV_Link"/>
    <child link="LF_driving_Link"/>
    <axis xyz="0 1 0"/>
    <limit effort="5" lower="-0.78539816339" upper="1.57079632679" velocity="5"/>
    <dynamics damping="0.1" friction="0.4"/>
  </joint>
  <link name="LF_gripper_Link">
    <inertial>
      <origin rpy="0 0 0" xyz="0.0710296935233056 0.0037135355484196 -0.00222742536711223"/>
      <mass value="0.415840817883391"/>
      <inertia ixx="0.000103581229161757" ixy="-5.56154912627397E-07" ixz="1.25700028997968E-06" iyy="5.98220979474832E-05" iyz="-5.92848495250994E-08" izz="8.09792661333327E-05"/>
    </inertial>
    <visual>
      <origin rpy="0 0 0" xyz="0 0 0"/>
      <geometry>
        <mesh filename="file:///home/ale/lbr_ws/install/lbr_description/share/lbr_description/meshes/Grieel_gripper_mode/gripper_Link.STL"/>
      </geometry>
      <material name="">
        <color rgba="0.2 0.2 0.2 1"/>
      </material>
    </visual>
    <collision name="LF_gripper_Link_collision">
      <origin rpy="0 0 0" xyz="0 0 0"/>
      <geometry>
        <mesh filename="file:///home/ale/lbr_ws/install/lbr_description/share/lbr_description/meshes/Grieel_gripper_mode/gripper_Link.STL"/>
      </geometry>
    </collision>
  </link>
  <joint name="LF_driving" type="continuous">
    <origin rpy="0 0 0" xyz="0.0131 0 0.04576"/>
    <parent link="LF_driving_Link"/>
    <child link="LF_gripper_Link"/>
    <axis xyz="-1 0 0"/>
    <dynamics damping="0.1" friction="0.4"/>
  </joint>
  <!-- Gazebo plugin for contact sensor, collision name like that because of parsing errors in the urdf  -->
  <gazebo reference="LF_gripper_Link">
    <sensor name="LF_gripper_bumper_sensor" type="contact">
      <always_on>true</always_on>
      <update_rate>100</update_rate>
      <contact>
        <collision>LF_gripper_Link_collision_collision</collision>
      </contact>
      <plugin filename="libgazebo_ros_bumper.so" name="LF_gripper_bumper">
        <ros>
          <namespace>LF</namespace>
        </ros>
        <frame_name>LF_gripper_link</frame_name>
      </plugin>
    </sensor>
  </gazebo>
  <!-- <xacro:grieel_gripper_macro prefix="LH" parent="LH"/>
    <xacro:grieel_gripper_macro prefix="RH" parent="RH"/>
    <xacro:grieel_gripper_macro prefix="RF" parent="RF"/> -->
  <ros2_control name="LF_ros2_control" type="system">
    <hardware>
      <plugin>gazebo_ros2_control/GazeboSystem</plugin>
    </hardware>
    <joint name="LF_B2C">
      <command_interface name="position">
        <param name="min">-10</param>
        <param name="max">10</param>
      </command_interface>
      <command_interface name="velocity">
        <param name="min">-0.5</param>
        <param name="max">0.5</param>
      </command_interface>
      <command_interface name="effort">
        <param name="min">-10</param>
        <param name="max">10</param>
      </command_interface>
      <state_interface name="position">
        <!-- Set initial joint position -->
        <param name="initial_value"> 0.0 </param>
      </state_interface>
      <state_interface name="velocity"/>
    </joint>
    <joint name="LF_C2F">
      <command_interface name="position">
        <param name="min">-10</param>
        <param name="max">10</param>
      </command_interface>
      <command_interface name="velocity">
        <param name="min">-0.5</param>
        <param name="max">0.5</param>
      </command_interface>
      <command_interface name="effort">
        <param name="min">-10</param>
        <param name="max">10</param>
      </command_interface>
      <state_interface name="position">
        <param name="initial_value"> 0.0 </param>
      </state_interface>
      <state_interface name="velocity"/>
    </joint>
    <joint name="LF_F2T">
      <command_interface name="position">
        <param name="min">-10</param>
        <param name="max">10</param>
      </command_interface>
      <command_interface name="velocity">
        <param name="min">-0.5</param>
        <param name="max">0.5</param>
      </command_interface>
      <command_interface name="effort">
        <param name="min">-10</param>
        <param name="max">10</param>
      </command_interface>
      <state_interface name="position">
        <param name="initial_value"> 1.5707963267948966 </param>
      </state_interface>
      <state_interface name="velocity"/>
    </joint>
    <joint name="LF_T2E">
      <command_interface name="position">
        <param name="min">-10</param>
        <param name="max">10</param>
      </command_interface>
      <command_interface name="velocity">
        <param name="min">-0.5</param>
        <param name="max">0.5</param>
      </command_interface>
      <command_interface name="effort">
        <param name="min">-10</param>
        <param name="max">10</param>
      </command_interface>
      <state_interface name="position">
        <param name="initial_value"> 0.0 </param>
      </state_interface>
      <state_interface name="velocity"/>
    </joint>
    <joint name="LF_wristH">
      <command_interface name="position">
        <param name="min">-10</param>
        <param name="max">10</param>
      </command_interface>
      <command_interface name="velocity">
        <param name="min">-0.5</param>
        <param name="max">0.5</param>
      </command_interface>
      <command_interface name="effort">
        <param name="min">-10</param>
        <param name="max">10</param>
      </command_interface>
      <state_interface name="position">
        <param name="initial_value"> 0.0 </param>
      </state_interface>
      <state_interface name="velocity"/>
    </joint>
    <joint name="LF_wristV">
      <command_interface name="position">
        <param name="min">-10</param>
        <param name="max">10</param>
      </command_interface>
      <command_interface name="velocity">
        <param name="min">-0.5</param>
        <param name="max">0.5</param>
      </command_interface>
      <command_interface name="effort">
        <param name="min">-10</param>
        <param name="max">10</param>
      </command_interface>
      <state_interface name="position">
        <param name="initial_value"> 0.0 </param>
      </state_interface>
      <state_interface name="velocity"/>
    </joint>
    <joint name="LF_driving">
      <command_interface name="position">
        <param name="min">-10</param>
        <param name="max">10</param>
      </command_interface>
      <command_interface name="velocity">
        <param name="min">-0.5</param>
        <param name="max">0.5</param>
      </command_interface>
      <command_interface name="effort">
        <param name="min">-10</param>
        <param name="max">10</param>
      </command_interface>
      <state_interface name="position">
        <param name="initial_value"> 0.0 </param>
      </state_interface>
      <state_interface name="velocity"/>
    </joint>
  </ros2_control>
  <!-- <xacro:ros2_control_macro prefix="LH"/>
  <xacro:ros2_control_macro prefix="RH"/>
  <xacro:ros2_control_macro prefix="RF"/> -->
  <!-- Gazebo plugin for joint state publisher  -->
  <gazebo>
    <plugin filename="libgazebo_ros_joint_state_publisher.so" name="LF_joint_state">
      <ros>
        <namespace>LF</namespace>
        <remapping>~/out:=joint_states</remapping>
      </ros>
      <update_rate>30</update_rate>
      <!-- <joint_name>${prefix}_E2grieel</joint_name> -->
      <joint_name>LF_B2C</joint_name>
      <joint_name>LF_C2F</joint_name>
      <joint_name>LF_F2T</joint_name>
      <joint_name>LF_T2E</joint_name>
      <joint_name>LF_wristH</joint_name>
      <joint_name>LF_wristV</joint_name>
      <joint_name>LF_driving</joint_name>
    </plugin>
  </gazebo>
  <!-- <xacro:joint_state_macro prefix="LH"/>
  <xacro:joint_state_macro prefix="RH"/>
  <xacro:joint_state_macro prefix="RF"/> -->
  <gazebo reference="LF_gripper_Link">
    <mu1>0.5</mu1>
    <mu2>0.5</mu2>
    <kp>1000000</kp>
    <kd>1.0</kd>
  </gazebo>
  <gazebo reference="LF_femur">
    <material>Gazebo/Black</material>
    <visual>
      <material>
        <ambient>0.2 0.2 0.2 1</ambient>
        <diffuse>0.2 0.2 0.2 1</diffuse>
        <specular>0.01 0.01 0.01 1</specular>
        <emissive>0.01 0.01 0.01 1</emissive>
      </material>
    </visual>
  </gazebo>
  <gazebo reference="LF_tibia">
    <material>Gazebo/Black</material>
    <visual>
      <material>
        <ambient>0.2 0.2 0.2 1</ambient>
        <diffuse>0.2 0.2 0.2 1</diffuse>
        <specular>0.01 0.01 0.01 1</specular>
        <emissive>0.01 0.01 0.01 1</emissive>
      </material>
    </visual>
  </gazebo>
  <gazebo reference="LF_limb_end">
    <material>Gazebo/Black</material>
    <visual>
      <material>
        <ambient>0.2 0.2 0.2 1</ambient>
        <diffuse>0.2 0.2 0.2 1</diffuse>
        <specular>0.01 0.01 0.01 1</specular>
        <emissive>0.01 0.01 0.01 1</emissive>
      </material>
    </visual>
  </gazebo>
  <gazebo reference="LF_limb_root">
    <material>Gazebo/Black</material>
    <visual>
      <material>
        <ambient>0.2 0.2 0.2 1</ambient>
        <diffuse>0.2 0.2 0.2 1</diffuse>
        <specular>0.01 0.01 0.01 1</specular>
        <emissive>0.01 0.01 0.01 1</emissive>
      </material>
    </visual>
  </gazebo>
  <gazebo reference="LF_coxa">
    <material>Gazebo/Black</material>
    <visual>
      <material>
        <ambient>0.2 0.2 0.2 1</ambient>
        <diffuse>0.2 0.2 0.2 1</diffuse>
        <specular>0.01 0.01 0.01 1</specular>
        <emissive>0.01 0.01 0.01 1</emissive>
      </material>
    </visual>
  </gazebo>
  <gazebo reference="LF_wristH_Link">
    <material>Gazebo/Black</material>
    <visual>
      <material>
        <ambient>0.2 0.2 0.2 1</ambient>
        <diffuse>0.2 0.2 0.2 1</diffuse>
        <specular>0.01 0.01 0.01 1</specular>
        <emissive>0.01 0.01 0.01 1</emissive>
      </material>
    </visual>
  </gazebo>
  <gazebo reference="LF_wristV_Link">
    <material>Gazebo/Black</material>
    <visual>
      <material>
        <ambient>0.2 0.2 0.2 1</ambient>
        <diffuse>0.2 0.2 0.2 1</diffuse>
        <specular>0.01 0.01 0.01 1</specular>
        <emissive>0.01 0.01 0.01 1</emissive>
      </material>
    </visual>
  </gazebo>
  <gazebo reference="LF_driving_Link">
    <material>Gazebo/Black</material>
    <visual>
      <material>
        <ambient>0.2 0.2 0.2 1</ambient>
        <diffuse>0.2 0.2 0.2 1</diffuse>
        <specular>0.01 0.01 0.01 1</specular>
        <emissive>0.01 0.01 0.01 1</emissive>
      </material>
    </visual>
  </gazebo>
  <gazebo reference="LF_gripper_Link">
    <material>Gazebo/Black</material>
    <visual>
      <material>
        <ambient>0.2 0.2 0.2 1</ambient>
        <diffuse>0.2 0.2 0.2 1</diffuse>
        <specular>0.01 0.01 0.01 1</specular>
        <emissive>0.01 0.01 0.01 1</emissive>
      </material>
    </visual>
  </gazebo>
  <gazebo reference="LF_wheel_Link">
    <material>Gazebo/Black</material>
    <visual>
      <material>
        <ambient>0.2 0.2 0.2 1</ambient>
        <diffuse>0.2 0.2 0.2 1</diffuse>
        <specular>0.01 0.01 0.01 1</specular>
        <emissive>0.01 0.01 0.01 1</emissive>
      </material>
    </visual>
  </gazebo>
  <!-- <xacro:gazebo_phisics_macro prefix="LH"/>
  <xacro:gazebo_phisics_macro prefix="RH"/>
  <xacro:gazebo_phisics_macro prefix="RF"/> -->
</robot>
