<?xml version="1.0" ?>
<!-- =================================================================================== -->
<!-- |    This document was autogenerated by xacro from LIMBERO_UPDATE.xacro           | -->
<!-- |    EDITING THIS FILE BY HAND IS NOT RECOMMENDED                                 | -->
<!-- =================================================================================== -->
<robot name="LIMBERO">
  <gazebo>
    <!-- ros_control plugin -->
    <plugin filename="libgazebo_ros2_control.so" name="gazebo_ros2_control">
      <parameters>/home/ale/lbr_ws/install/lbr_description/share/lbr_description/config/lbr_controller_with_grieel.yaml</parameters>
    </plugin>
  </gazebo>
  <link name="base_link">
    <inertial>
      <origin rpy="0 0 0" xyz="0 0 -0.0030083"/>
      <mass value="3.1152"/>
      <inertia ixx="0.0036482" ixy="7.8081E-07" ixz="1.7521E-06" iyy="0.0062179" iyz="-1.4424E-06" izz="0.0034682"/>
    </inertial>
    <visual>
      <origin rpy="0 0 0" xyz="0 0 0"/>
      <geometry>
        <mesh filename="file:///home/ale/lbr_ws/install/lbr_description/share/lbr_description/meshes/base.STL" scale="1.0 1.0 1.0"/>
      </geometry>
      <material name="">
        <color rgba="0.2 0.2 0.2 1"/>
      </material>
    </visual>
    <collision>
      <origin rpy="0 0 0" xyz="0 0 0"/>
      <geometry>
        <mesh filename="file:///home/ale/lbr_ws/install/lbr_description/share/lbr_description/meshes/base.STL" scale="1.0 1.0 1.0"/>
      </geometry>
    </collision>
  </link>
  <gazebo reference="base_link">
    <material>Gazebo/Black</material>
    <visual>
      <material>
        <ambient>0.2 0.2 0.2 1</ambient>
        <diffuse>0.2 0.2 0.2 1</diffuse>
        <specular>0.01 0.01 0.01 1</specular>
        <emissive>0.01 0.01 0.01 1</emissive>
      </material>
    </visual>
  </gazebo>
  <joint name="LF_joint" type="fixed">
    <origin rpy="0 0 0.7853981633974483" xyz="0.14142135623730953 0.1414213562373095 0"/>
    <parent link="base_link"/>
    <child link="LF_limb_root"/>
  </joint>
  <link name="LF_limb_root">
    <inertial>
      <origin rpy="0 0 0" xyz="-0.015029 -7.7571E-11 -0.047318"/>
      <mass value="0.08459"/>
      <inertia ixx="2.1548E-05" ixy="-4.775E-14" ixz="-1.6188E-07" iyy="3.834E-05" iyz="-8.2973E-14" izz="3.1728E-05"/>
    </inertial>
    <visual>
      <origin rpy="0 0 0" xyz="0 0 0"/>
      <geometry>
        <mesh filename="file:///home/ale/lbr_ws/install/lbr_description/share/lbr_description/meshes/limb_root.STL"/>
      </geometry>
      <material name="">
        <color rgba="0.2 0.2 0.2 1"/>
      </material>
    </visual>
    <collision>
      <origin rpy="0 0 0" xyz="0 0 0"/>
      <geometry>
        <mesh filename="file:///home/ale/lbr_ws/install/lbr_description/share/lbr_description/meshes/limb_root.STL"/>
      </geometry>
    </collision>
  </link>
  <link name="LF_coxa">
    <inertial>
      <origin rpy="0 0 0" xyz="0.015938 0.00063302 -0.0015013"/>
      <mass value="0.09109"/>
      <inertia ixx="2.352E-05" ixy="-1.6188E-07" ixz="4.775E-14" iyy="3.3634E-05" iyz="8.2973E-14" izz="4.2122E-05"/>
    </inertial>
    <visual>
      <origin rpy="0 0 0" xyz="0 0 0"/>
      <geometry>
        <mesh filename="file:///home/ale/lbr_ws/install/lbr_description/share/lbr_description/meshes/coxa.STL"/>
      </geometry>
      <material name="">
        <color rgba="0.2 0.2 0.2 1"/>
      </material>
    </visual>
    <collision>
      <origin rpy="0 0 0" xyz="0 0 0"/>
      <geometry>
        <mesh filename="file:///home/ale/lbr_ws/install/lbr_description/share/lbr_description/meshes/coxa.STL"/>
      </geometry>
    </collision>
  </link>
  <joint name="LF_B2C" type="revolute">
    <origin rpy="0 0 0" xyz="0 0 0"/>
    <parent link="LF_limb_root"/>
    <child link="LF_coxa"/>
    <axis xyz="0 0 1"/>
    <limit effort="5" lower="-3.14" upper="3.14" velocity="5"/>
    <dynamics damping="0.1" friction="0.4"/>
  </joint>
  <link name="LF_femur">
    <inertial>
      <origin rpy="0 0 0" xyz="0.10083 0.00014739 -3.217E-08"/>
      <mass value="0.12821"/>
      <inertia ixx="3.7005E-05" ixy="-1.9987E-08" ixz="-3.8346E-12" iyy="2.9934E-05" iyz="2.5988E-11" izz="4.8164E-05"/>
    </inertial>
    <visual>
      <origin rpy="0 0 0" xyz="0 0 0"/>
      <geometry>
        <mesh filename="file:///home/ale/lbr_ws/install/lbr_description/share/lbr_description/meshes/femur.STL"/>
      </geometry>
      <material name="">
        <color rgba="0.2 0.2 0.2 1"/>
      </material>
    </visual>
    <collision>
      <origin rpy="0 0 0" xyz="0 0 0"/>
      <geometry>
        <mesh filename="file:///home/ale/lbr_ws/install/lbr_description/share/lbr_description/meshes/femur.STL"/>
      </geometry>
    </collision>
  </link>
  <joint name="LF_C2F" type="revolute">
    <origin rpy="0 0 0" xyz="0.031 0 0"/>
    <parent link="LF_coxa"/>
    <child link="LF_femur"/>
    <axis xyz="0 1 0"/>
    <limit effort="5" lower="-3.14" upper="3.14" velocity="5"/>
    <dynamics damping="0.1" friction="0.4"/>
  </joint>
  <link name="LF_tibia">
    <inertial>
      <origin rpy="0 0 0" xyz="0.10298 1.1638E-07 0.019231"/>
      <mass value="0.061841"/>
      <inertia ixx="1.5486E-05" ixy="4.7072E-09" ixz="2.5637E-06" iyy="2.1826E-05" iyz="2.414E-08" izz="2.8843E-05"/>
    </inertial>
    <visual>
      <origin rpy="0 0 0" xyz="0 0 0"/>
      <geometry>
        <mesh filename="file:///home/ale/lbr_ws/install/lbr_description/share/lbr_description/meshes/tibia.STL"/>
      </geometry>
      <material name="">
        <color rgba="0.2 0.2 0.2 1"/>
      </material>
    </visual>
    <collision>
      <origin rpy="0 0 0" xyz="0 0 0"/>
      <geometry>
        <mesh filename="file:///home/ale/lbr_ws/install/lbr_description/share/lbr_description/meshes/tibia.STL"/>
      </geometry>
    </collision>
  </link>
  <joint name="LF_F2T" type="revolute">
    <origin rpy="0 0 0" xyz="0.2 0 0"/>
    <parent link="LF_femur"/>
    <child link="LF_tibia"/>
    <axis xyz="0 1 0"/>
    <limit effort="5" lower="-3.14" upper="3.14" velocity="5"/>
    <dynamics damping="0.1" friction="0.4"/>
  </joint>
  <link name="LF_limb_end">
    <inertial>
      <origin rpy="0 0 0" xyz="-0.011645 0.00042918 -9.53E-12"/>
      <mass value="0.081999"/>
      <inertia ixx="1.3061E-05" ixy="-3.7211E-08" ixz="3.1094E-14" iyy="1.9634E-05" iyz="-3.9438E-17" izz="2.2308E-05"/>
    </inertial>
    <visual>
      <origin rpy="0 0 0" xyz="0 0 0"/>
      <geometry>
        <mesh filename="file:///home/ale/lbr_ws/install/lbr_description/share/lbr_description/meshes/limb_end.STL"/>
      </geometry>
      <material name="">
        <color rgba="0.2 0.2 0.2 1"/>
      </material>
    </visual>
    <collision>
      <origin rpy="0 0 0" xyz="0 0 0"/>
      <geometry>
        <mesh filename="file:///home/ale/lbr_ws/install/lbr_description/share/lbr_description/meshes/limb_end.STL"/>
      </geometry>
    </collision>
  </link>
  <joint name="LF_T2E" type="revolute">
    <origin rpy="0 0 0" xyz="0.2 0 0"/>
    <parent link="LF_tibia"/>
    <child link="LF_limb_end"/>
    <axis xyz="0 1 0"/>
    <limit effort="5" lower="-3.14" upper="3.14" velocity="5"/>
    <dynamics damping="0.1" friction="0.4"/>
  </joint>
  <!-- <xacro:limb_macro prefix="LH" parent="base_link" radius="135"/>
  <xacro:limb_macro prefix="RH" parent="base_link" radius="225"/>
  <xacro:limb_macro prefix="RF" parent="base_link" radius="315"/> -->
  <joint name="LF_E2grieel" type="fixed">
    <origin rpy="0 0 0" xyz="0 0 0"/>
    <parent link="LF_limb_end"/>
    <child link="LF_wristH_Link"/>
    <!-- <axis
        xyz="0 1 0" />
      <limit
        lower="0"
        upper="0"
        effort="5"
        velocity="0" /> -->
  </joint>
  <link name="LF_wristH_Link">
    <inertial>
      <origin rpy="0 0 0" xyz="-0.00522566844956051 -1.34546419111017E-16 -2.50808033407652E-17"/>
      <mass value="0.00988435774287047"/>
      <inertia ixx="2.66612744764484E-06" ixy="-1.34713298418369E-20" ixz="3.60089715947716E-21" iyy="4.57142030143529E-06" iyz="4.76175575235816E-19" izz="2.9211242466353E-06"/>
    </inertial>
    <visual>
      <origin rpy="0 0 0" xyz="0 0 0"/>
      <geometry>
        <mesh filename="file:///home/ale/lbr_ws/install/lbr_description/share/lbr_description/meshes/Grieel_wheel_mode/wristH_Link.STL"/>
      </geometry>
      <material name="">
        <color rgba="0.2 0.2 0.2 1"/>
      </material>
    </visual>
    <collision>
      <origin rpy="0 0 0" xyz="0 0 0"/>
      <geometry>
        <mesh filename="file:///home/ale/lbr_ws/install/lbr_description/share/lbr_description/meshes/Grieel_wheel_mode/wristH_Link.STL"/>
      </geometry>
    </collision>
  </link>
  <link name="LF_wristV_Link">
    <inertial>
      <origin rpy="0 0 0" xyz="0.0195120824576142 -0.000473380302575917 -0.0113217579335182"/>
      <mass value="0.102059813857681"/>
      <inertia ixx="2.51506057023328E-05" ixy="5.87568310882065E-07" ixz="5.02138918676071E-10" iyy="2.47069145197251E-05" iyz="-1.31422853272996E-09" izz="1.79824315026287E-05"/>
    </inertial>
    <visual>
      <origin rpy="-3.14159265358 0 0" xyz="-0.014255 0 0"/>
      <geometry>
        <mesh filename="file:///home/ale/lbr_ws/install/lbr_description/share/lbr_description/meshes/Grieel_wheel_mode/wristV_Link.STL"/>
      </geometry>
      <material name="">
        <color rgba="0.2 0.2 0.2 1"/>
      </material>
    </visual>
    <collision>
      <origin rpy="0 0 0" xyz="-0.014255 0 0"/>
      <geometry>
        <mesh filename="file:///home/ale/lbr_ws/install/lbr_description/share/lbr_description/meshes/Grieel_wheel_mode/wristV_Link.STL"/>
      </geometry>
    </collision>
  </link>
  <joint name="LF_wristH" type="revolute">
    <origin rpy="0 0 0" xyz="0.014255 0 0"/>
    <parent link="LF_wristH_Link"/>
    <child link="LF_wristV_Link"/>
    <axis xyz="1 0 0"/>
    <limit effort="5" lower="-3.14159265358" upper="3.14159265358" velocity="5"/>
    <dynamics damping="0.1" friction="0.4"/>
  </joint>
  <link name="LF_driving_Link">
    <inertial>
      <origin rpy="0 0 0" xyz="0.0448909989381638 -0.00431415254067207 5.44808063318511E-05"/>
      <mass value="0.132659951309175"/>
      <inertia ixx="4.32511275712107E-05" ixy="-4.1427317823442E-09" ixz="7.08867361092382E-09" iyy="3.4691959624158E-05" iyz="-1.0616454627913E-08" izz="3.76031003493131E-05"/>
    </inertial>
    <visual>
      <origin rpy="3.14159265358 -1.5708 0" xyz="0.024002 0 -0.03325 "/>
      <geometry>
        <mesh filename="file:///home/ale/lbr_ws/install/lbr_description/share/lbr_description/meshes/Grieel_wheel_mode/driving_Link.STL"/>
      </geometry>
      <material name="">
        <color rgba="0.2 0.2 0.2 1"/>
      </material>
    </visual>
    <collision>
      <origin rpy="0 0 0" xyz="-0.03325 0 0.024002"/>
      <geometry>
        <mesh filename="file:///home/ale/lbr_ws/install/lbr_description/share/lbr_description/meshes/Grieel_wheel_mode/driving_Link.STL"/>
      </geometry>
    </collision>
  </link>
  <joint name="LF_wristV" type="revolute">
    <origin rpy="0 0 0" xyz="0.018995 0 0.024002"/>
    <parent link="LF_wristV_Link"/>
    <child link="LF_driving_Link"/>
    <axis xyz="0 1 0"/>
    <limit effort="5" lower="-2.35619449019" upper="1.5708" velocity="5"/>
    <dynamics damping="0.1" friction="0.4"/>
  </joint>
  <link name="LF_wheel_Link">
    <inertial>
      <origin rpy="0 0 0" xyz="0.00222516909085785 0.00371161518941796 0.0864468548098098"/>
      <mass value="0.415840945785028"/>
      <inertia ixx="8.46005758272478E-05" ixy="5.92848495177423E-08" ixz="-1.25700028998783E-06" iyy="6.34434076414387E-05" iyz="-5.56154912625676E-07" izz="9.63386112584046E-05"/>
    </inertial>
    <visual>
      <origin rpy="0 -1.5708 3.14159265358" xyz=" 0.010898 0 -0.079017"/>
      <geometry>
        <mesh filename="file:///home/ale/lbr_ws/install/lbr_description/share/lbr_description/meshes/Grieel_wheel_mode/wheel_Link.STL"/>
      </geometry>
      <material name="">
        <color rgba="0.2 0.2 0.2 1"/>
      </material>
    </visual>
    <collision name="LF_wheel_Link_collision">
      <origin rpy="0 0 0" xyz="-0.079017 0 0.010898"/>
      <geometry>
        <mesh filename="file:///home/ale/lbr_ws/install/lbr_description/share/lbr_description/meshes/Grieel_wheel_mode/wheel_Link.STL"/>
      </geometry>
    </collision>
    <!-- <collision name="${prefix}_wheel_Link_collision">
      <origin
        xyz="0 -0.118 0"
        rpy="${pi/2} 0 0" />
      <geometry>
        <cylinder length="0.04" radius="0.078"/>
      </geometry>
    </collision> -->
  </link>
  <joint name="LF_driving" type="continuous">
    <origin rpy="0 0 0" xyz="0.013104 0 0.045762"/>
    <parent link="LF_driving_Link"/>
    <child link="LF_wheel_Link"/>
    <axis xyz="-1 0 0"/>
    <dynamics damping="0.1" friction="0.4"/>
  </joint>
  <!-- Gazebo plugin for contact sensor, collision name like that because of parsing errors in the urdf  -->
  <gazebo reference="LF_wheel_Link">
    <sensor name="LF_gripper_bumper_sensor" type="contact">
      <always_on>true</always_on>
      <update_rate>100</update_rate>
      <contact>
        <collision>LF_wheel_Link_collision_collision</collision>
      </contact>
      <plugin filename="libgazebo_ros_bumper.so" name="LF_gripper_bumper">
        <ros>
          <namespace>LF</namespace>
        </ros>
        <frame_name>LF_wheel_link</frame_name>
      </plugin>
    </sensor>
  </gazebo>
  <!-- <xacro:grieel_wheel_macro prefix="LH" parent="LH"/>
    <xacro:grieel_wheel_macro prefix="RH" parent="RH"/>
    <xacro:grieel_gripper_macro prefix="RF" parent="RF"/> -->
  <ros2_control name="LF_ros2_control" type="system">
    <hardware>
      <plugin>gazebo_ros2_control/GazeboSystem</plugin>
    </hardware>
    <joint name="LF_B2C">
      <command_interface name="position">
        <param name="min">-10</param>
        <param name="max">10</param>
      </command_interface>
      <command_interface name="velocity">
        <param name="min">-0.5</param>
        <param name="max">0.5</param>
      </command_interface>
      <command_interface name="effort">
        <param name="min">-10</param>
        <param name="max">10</param>
      </command_interface>
      <state_interface name="position">
        <!-- Set initial joint position -->
        <param name="initial_value"> 0.0 </param>
      </state_interface>
      <state_interface name="velocity"/>
    </joint>
    <joint name="LF_C2F">
      <command_interface name="position">
        <param name="min">-10</param>
        <param name="max">10</param>
      </command_interface>
      <command_interface name="velocity">
        <param name="min">-0.5</param>
        <param name="max">0.5</param>
      </command_interface>
      <command_interface name="effort">
        <param name="min">-10</param>
        <param name="max">10</param>
      </command_interface>
      <state_interface name="position">
        <param name="initial_value"> 0.0 </param>
      </state_interface>
      <state_interface name="velocity"/>
    </joint>
    <joint name="LF_F2T">
      <command_interface name="position">
        <param name="min">-10</param>
        <param name="max">10</param>
      </command_interface>
      <command_interface name="velocity">
        <param name="min">-0.5</param>
        <param name="max">0.5</param>
      </command_interface>
      <command_interface name="effort">
        <param name="min">-10</param>
        <param name="max">10</param>
      </command_interface>
      <state_interface name="position">
        <param name="initial_value"> 1.5707963267948966 </param>
      </state_interface>
      <state_interface name="velocity"/>
    </joint>
    <joint name="LF_T2E">
      <command_interface name="position">
        <param name="min">-10</param>
        <param name="max">10</param>
      </command_interface>
      <command_interface name="velocity">
        <param name="min">-0.5</param>
        <param name="max">0.5</param>
      </command_interface>
      <command_interface name="effort">
        <param name="min">-10</param>
        <param name="max">10</param>
      </command_interface>
      <state_interface name="position">
        <param name="initial_value"> 0.0 </param>
      </state_interface>
      <state_interface name="velocity"/>
    </joint>
    <joint name="LF_wristH">
      <command_interface name="position">
        <param name="min">-10</param>
        <param name="max">10</param>
      </command_interface>
      <command_interface name="velocity">
        <param name="min">-0.5</param>
        <param name="max">0.5</param>
      </command_interface>
      <command_interface name="effort">
        <param name="min">-10</param>
        <param name="max">10</param>
      </command_interface>
      <state_interface name="position">
        <param name="initial_value"> 0.0 </param>
      </state_interface>
      <state_interface name="velocity"/>
    </joint>
    <joint name="LF_wristV">
      <command_interface name="position">
        <param name="min">-10</param>
        <param name="max">10</param>
      </command_interface>
      <command_interface name="velocity">
        <param name="min">-0.5</param>
        <param name="max">0.5</param>
      </command_interface>
      <command_interface name="effort">
        <param name="min">-10</param>
        <param name="max">10</param>
      </command_interface>
      <state_interface name="position">
        <param name="initial_value"> 0.0 </param>
      </state_interface>
      <state_interface name="velocity"/>
    </joint>
    <joint name="LF_driving">
      <command_interface name="position">
        <param name="min">-10</param>
        <param name="max">10</param>
      </command_interface>
      <command_interface name="velocity">
        <param name="min">-0.5</param>
        <param name="max">0.5</param>
      </command_interface>
      <command_interface name="effort">
        <param name="min">-10</param>
        <param name="max">10</param>
      </command_interface>
      <state_interface name="position">
        <param name="initial_value"> 0.0 </param>
      </state_interface>
      <state_interface name="velocity"/>
    </joint>
  </ros2_control>
  <!-- <xacro:ros2_control_macro prefix="LH"/>
  <xacro:ros2_control_macro prefix="RH"/>
  <xacro:ros2_control_macro prefix="RF"/> -->
  <!-- Gazebo plugin for joint state publisher  -->
  <gazebo>
    <plugin filename="libgazebo_ros_joint_state_publisher.so" name="LF_joint_state">
      <ros>
        <namespace>LF</namespace>
        <remapping>~/out:=joint_states</remapping>
      </ros>
      <update_rate>30</update_rate>
      <!-- <joint_name>${prefix}_E2grieel</joint_name> -->
      <joint_name>LF_B2C</joint_name>
      <joint_name>LF_C2F</joint_name>
      <joint_name>LF_F2T</joint_name>
      <joint_name>LF_T2E</joint_name>
      <joint_name>LF_wristH</joint_name>
      <joint_name>LF_wristV</joint_name>
      <joint_name>LF_driving</joint_name>
    </plugin>
  </gazebo>
  <!-- <xacro:joint_state_macro prefix="LH"/>
  <xacro:joint_state_macro prefix="RH"/>
  <xacro:joint_state_macro prefix="RF"/> -->
  <gazebo reference="LF_wheel_Link">
    <mu1>1.5</mu1>
    <mu2>2.5</mu2>
    <kp>1000000</kp>
    <kd>1.0</kd>
  </gazebo>
  <gazebo reference="LF_femur">
    <material>Gazebo/Black</material>
    <visual>
      <material>
        <ambient>0.2 0.2 0.2 1</ambient>
        <diffuse>0.2 0.2 0.2 1</diffuse>
        <specular>0.01 0.01 0.01 1</specular>
        <emissive>0.01 0.01 0.01 1</emissive>
      </material>
    </visual>
  </gazebo>
  <gazebo reference="LF_tibia">
    <material>Gazebo/Black</material>
    <visual>
      <material>
        <ambient>0.2 0.2 0.2 1</ambient>
        <diffuse>0.2 0.2 0.2 1</diffuse>
        <specular>0.01 0.01 0.01 1</specular>
        <emissive>0.01 0.01 0.01 1</emissive>
      </material>
    </visual>
  </gazebo>
  <gazebo reference="LF_limb_end">
    <material>Gazebo/Black</material>
    <visual>
      <material>
        <ambient>0.2 0.2 0.2 1</ambient>
        <diffuse>0.2 0.2 0.2 1</diffuse>
        <specular>0.01 0.01 0.01 1</specular>
        <emissive>0.01 0.01 0.01 1</emissive>
      </material>
    </visual>
  </gazebo>
  <gazebo reference="LF_limb_root">
    <material>Gazebo/Black</material>
    <visual>
      <material>
        <ambient>0.2 0.2 0.2 1</ambient>
        <diffuse>0.2 0.2 0.2 1</diffuse>
        <specular>0.01 0.01 0.01 1</specular>
        <emissive>0.01 0.01 0.01 1</emissive>
      </material>
    </visual>
  </gazebo>
  <gazebo reference="LF_coxa">
    <material>Gazebo/Black</material>
    <visual>
      <material>
        <ambient>0.2 0.2 0.2 1</ambient>
        <diffuse>0.2 0.2 0.2 1</diffuse>
        <specular>0.01 0.01 0.01 1</specular>
        <emissive>0.01 0.01 0.01 1</emissive>
      </material>
    </visual>
  </gazebo>
  <gazebo reference="LF_wristH_Link">
    <material>Gazebo/Black</material>
    <visual>
      <material>
        <ambient>0.2 0.2 0.2 1</ambient>
        <diffuse>0.2 0.2 0.2 1</diffuse>
        <specular>0.01 0.01 0.01 1</specular>
        <emissive>0.01 0.01 0.01 1</emissive>
      </material>
    </visual>
  </gazebo>
  <gazebo reference="LF_wristV_Link">
    <material>Gazebo/Black</material>
    <visual>
      <material>
        <ambient>0.2 0.2 0.2 1</ambient>
        <diffuse>0.2 0.2 0.2 1</diffuse>
        <specular>0.01 0.01 0.01 1</specular>
        <emissive>0.01 0.01 0.01 1</emissive>
      </material>
    </visual>
  </gazebo>
  <gazebo reference="LF_driving_Link">
    <material>Gazebo/Black</material>
    <visual>
      <material>
        <ambient>0.2 0.2 0.2 1</ambient>
        <diffuse>0.2 0.2 0.2 1</diffuse>
        <specular>0.01 0.01 0.01 1</specular>
        <emissive>0.01 0.01 0.01 1</emissive>
      </material>
    </visual>
  </gazebo>
  <gazebo reference="LF_gripper_Link">
    <material>Gazebo/Black</material>
    <visual>
      <material>
        <ambient>0.2 0.2 0.2 1</ambient>
        <diffuse>0.2 0.2 0.2 1</diffuse>
        <specular>0.01 0.01 0.01 1</specular>
        <emissive>0.01 0.01 0.01 1</emissive>
      </material>
    </visual>
  </gazebo>
  <gazebo reference="LF_wheel_Link">
    <material>Gazebo/Black</material>
    <visual>
      <material>
        <ambient>0.2 0.2 0.2 1</ambient>
        <diffuse>0.2 0.2 0.2 1</diffuse>
        <specular>0.01 0.01 0.01 1</specular>
        <emissive>0.01 0.01 0.01 1</emissive>
      </material>
    </visual>
  </gazebo>
  <!-- <xacro:gazebo_phisics_macro prefix="LH"/>
  <xacro:gazebo_phisics_macro prefix="RH"/>
  <xacro:gazebo_phisics_macro prefix="RF"/> -->
</robot>
